<!-- chassis-->
<robot name="mycar">
    <!-- add a small footprint and connect to baselink-->
    <link name="base_footprint">
        <visual>
            <geometry>
                <box size="0.001 0.001 0.001"/>
            </geometry>
            <origin xyz="0 0 0" rpy="0 0 0"/>
            <material name="car_color">
                <color rgba="0.8 0.5 0 0.5"/>
            </material>
        </visual>
    </link>

    <!--chasiss link-->
    <link name="base_link">
        <visual>
            <geometry>
                <box size="0.3 0.2 0.1"/>
            </geometry>
            <origin xyz="0 0 0" rpy="0 0 0"/>
            <material name="car_color">
                <color rgba="0.8 0.5 0 0.5"/>
            </material>
        </visual>
    </link>

    <!-- camera link-->
    <link name="camera">
        <visual>
            <geometry>
                <box size="0.02 0.05 0.05"/>
            </geometry>
            <origin xyz="0 0 0.025" rpy="0 0 0"/>

            <material name="camera_color">
                <color rgba="0 0 1 0.5"/>
            </material>
        </visual>
    </link>

    <!-- joint link-->
    <joint name="camera2base" type="continuous">
        <!--parent link-->
        <parent link="base_link"/>
        <!--child link-->
        <child link="camera"/>
        <!--translation-->
        <origin xyz="0.12 0 0.05" rpy="0 0 0"/>
        <!--axis-->
        <axis xyz="0 0 1"/>
    </joint>

    <joint name="foor2baselink" type="fixed">
        <!--parent link-->
        <parent link="base_footprint"/>
        <!--child link-->
        <child link="base_link"/>
        <!--translation-->
        <origin xyz="0 0 0.05" rpy="0 0 0"/>

    </joint>
</robot>
